#include <iostream>
#include <stdexcept>

int main()
{
    try {
       
        // ...
        return 0;
    }
    catch(const std::exception &e) {
        std::cerr << "exception: " << e.what() << '\n';
        return 1;
    }
    catch(...) {
        std::cerr << "Oops: something went wrong\n";
        return 2;
    }
} 
